<sdf version='1.6'>
  <world name='default'>
    <light name='sun' type='directional'>
      <cast_shadows>1</cast_shadows>
      <pose frame=''>0 0 10 0 -0 0</pose>
      <diffuse>0.8 0.8 0.8 1</diffuse>
      <specular>0.2 0.2 0.2 1</specular>
      <attenuation>
        <range>1000</range>
        <constant>0.9</constant>
        <linear>0.01</linear>
        <quadratic>0.001</quadratic>
      </attenuation>
      <direction>-0.5 0.1 -0.9</direction>
    </light>
    <model name='ground_plane'>
      <static>1</static>
      <link name='link'>
        <collision name='collision'>
          <geometry>
            <plane>
              <normal>0 0 1</normal>
              <size>100 100</size>
            </plane>
          </geometry>
          <surface>
            <contact>
              <collide_bitmask>65535</collide_bitmask>
              <ode/>
            </contact>
            <friction>
              <ode>
                <mu>100</mu>
                <mu2>50</mu2>
              </ode>
              <torsional>
                <ode/>
              </torsional>
            </friction>
            <bounce/>
          </surface>
          <max_contacts>10</max_contacts>
        </collision>
        <visual name='visual'>
          <cast_shadows>0</cast_shadows>
          <geometry>
            <plane>
              <normal>0 0 1</normal>
              <size>100 100</size>
            </plane>
          </geometry>
          <material>
            <script>
              <uri>file://media/materials/scripts/gazebo.material</uri>
              <name>Gazebo/Grey</name>
            </script>
          </material>
        </visual>
        <self_collide>0</self_collide>
        <enable_wind>0</enable_wind>
        <kinematic>0</kinematic>
      </link>
    </model>
    <physics name='default_physics' default='0' type='ode'>
      <real_time_update_rate>0</real_time_update_rate>
      <max_step_size>0.005</max_step_size>
      <real_time_factor>1</real_time_factor>
      <ode>
        <solver>
          <type>quick</type>
          <iters>150</iters>
          <precon_iters>0</precon_iters>
          <sor>1.4</sor>
          <use_dynamic_moi_rescaling>1</use_dynamic_moi_rescaling>
        </solver>
        <constraints>
          <cfm>1e-05</cfm>
          <erp>0.2</erp>
          <contact_max_correcting_vel>2000</contact_max_correcting_vel>
          <contact_surface_layer>0.01</contact_surface_layer>
        </constraints>
      </ode>
    </physics>
    <scene>
      <ambient>0.4 0.4 0.4 1</ambient>
      <background>0.7 0.7 0.7 1</background>
      <shadows>1</shadows>
    </scene>
    <gui fullscreen='0'>
      <camera name='user_camera'>
        <pose frame=''>0.740399 -0.691733 0.436942 0 0.275643 2.35619</pose>
        <view_controller>orbit</view_controller>
        <projection_type>perspective</projection_type>
      </camera>
    </gui>
    <light name='user_point_light_0' type='point'>
      <pose frame=''>0.012625 -0.010525 1 0 -0 0</pose>
      <diffuse>0.5 0.5 0.5 1</diffuse>
      <specular>0.1 0.1 0.1 1</specular>
      <attenuation>
        <range>20</range>
        <constant>0.5</constant>
        <linear>0.01</linear>
        <quadratic>0.001</quadratic>
      </attenuation>
      <cast_shadows>0</cast_shadows>
      <direction>0 0 -1</direction>
    </light>
    <gravity>0 0 -9.8</gravity>
    <magnetic_field>6e-06 2.3e-05 -4.2e-05</magnetic_field>
    <atmosphere type='adiabatic'/>
    <wind/>
    <spherical_coordinates>
      <surface_model>EARTH_WGS84</surface_model>
      <latitude_deg>0</latitude_deg>
      <longitude_deg>0</longitude_deg>
      <elevation>0</elevation>
      <heading_deg>0</heading_deg>
    </spherical_coordinates>
    <model name='crane_plus'>
      <link name='base_link'>
        <pose frame=''>0 0 0 0 -0 0</pose>
        <inertial>
          <pose frame=''>-0.000933 0 0.008833 0 -0 0</pose>
          <mass>0.003</mass>
          <inertia>
            <ixx>3</ixx>
            <ixy>0</ixy>
            <ixz>4.38667e-08</ixz>
            <iyy>3</iyy>
            <iyz>0</iyz>
            <izz>3</izz>
          </inertia>
        </inertial>
        <collision name='base_link_fixed_joint_lump__crane_plus_internal_mounting_plate_link_collision'>
          <pose frame=''>0 0 0.0005 0 -0 0</pose>
          <geometry>
            <box>
              <size>0.05 0.05 0.001</size>
            </box>
          </geometry>
          <max_contacts>10</max_contacts>
          <surface>
            <contact>
              <ode/>
            </contact>
            <bounce/>
            <friction>
              <torsional>
                <ode/>
              </torsional>
              <ode/>
            </friction>
          </surface>
        </collision>
        <collision name='base_link_fixed_joint_lump__crane_plus_internal_base_bracket_link_collision_1'>
          <pose frame=''>0 0 0.005 0 -0 0</pose>
          <geometry>
            <box>
              <size>0.022 0.032 0.008</size>
            </box>
          </geometry>
          <max_contacts>10</max_contacts>
          <surface>
            <contact>
              <ode/>
            </contact>
            <bounce/>
            <friction>
              <torsional>
                <ode/>
              </torsional>
              <ode/>
            </friction>
          </surface>
        </collision>
        <collision name='base_link_fixed_joint_lump__crane_plus_internal_shoulder_servo_link_collision_2'>
          <pose frame=''>-0.0013 0 0.024 0 -0 0</pose>
          <geometry>
            <box>
              <size>0.05 0.032 0.038</size>
            </box>
          </geometry>
          <max_contacts>10</max_contacts>
          <surface>
            <contact>
              <ode/>
            </contact>
            <bounce/>
            <friction>
              <torsional>
                <ode/>
              </torsional>
              <ode/>
            </friction>
          </surface>
        </collision>
        <visual name='base_link_fixed_joint_lump__crane_plus_internal_mounting_plate_link_visual'>
          <pose frame=''>-0.025 -0.025 0 0 -0 0</pose>
          <geometry>
            <mesh>
              <scale>1 1 1</scale>
              <uri>/home/charlene/catkin_ws/src/crane_plus_v2_motion_planning/crane_plus_description/meshes/mount.stl</uri>
            </mesh>
          </geometry>
        </visual>
        <visual name='base_link_fixed_joint_lump__crane_plus_internal_base_bracket_link_visual_1'>
          <pose frame=''>0 0 0.001 -1.57079 0 0</pose>
          <geometry>
            <mesh>
              <scale>0.01 0.01 0.01</scale>
              <uri>/home/charlene/catkin_ws/src/crane_plus_v2_motion_planning/crane_plus_description/meshes/f53.stl</uri>
            </mesh>
          </geometry>
        </visual>
        <visual name='base_link_fixed_joint_lump__crane_plus_internal_shoulder_servo_link_visual_2'>
          <pose frame=''>-0.0028 0 0.024 -1.57079 0 0</pose>
          <geometry>
            <mesh>
              <scale>0.001 0.001 0.001</scale>
              <uri>/home/charlene/catkin_ws/src/crane_plus_v2_motion_planning/crane_plus_description/meshes/ax12_box.stl</uri>
            </mesh>
          </geometry>
        </visual>
        <self_collide>0</self_collide>
        <enable_wind>0</enable_wind>
        <kinematic>0</kinematic>
      </link>
      <joint name='fixed' type='fixed'>
        <child>base_link</child>
        <parent>world</parent>
      </joint>
      <link name='crane_plus_shoulder_revolute_link'>
        <pose frame=''>-0.0163 0 0.045 0 -0 0</pose>
        <inertial>
          <pose frame=''>0 0 0.0005 0 -0 0</pose>
          <mass>0.001</mass>
          <inertia>
            <ixx>1</ixx>
            <ixy>0</ixy>
            <ixz>0</ixz>
            <iyy>1</iyy>
            <iyz>0</iyz>
            <izz>1</izz>
          </inertia>
        </inertial>
        <collision name='crane_plus_shoulder_revolute_link_collision'>
          <pose frame=''>0 0 0.01875 0 -0 0</pose>
          <geometry>
            <box>
              <size>0.025 0.0485 0.0375</size>
            </box>
          </geometry>
          <max_contacts>10</max_contacts>
          <surface>
            <contact>
              <ode/>
            </contact>
            <bounce/>
            <friction>
              <torsional>
                <ode/>
              </torsional>
              <ode/>
            </friction>
          </surface>
        </collision>
        <visual name='crane_plus_shoulder_revolute_link_visual'>
          <pose frame=''>0 0 0.0265 1.57079 -0 0</pose>
          <geometry>
            <mesh>
              <scale>0.001 0.001 0.001</scale>
              <uri>/home/charlene/catkin_ws/src/crane_plus_v2_motion_planning/crane_plus_description/meshes/f2.stl</uri>
            </mesh>
          </geometry>
        </visual>
        <self_collide>0</self_collide>
        <enable_wind>0</enable_wind>
        <kinematic>0</kinematic>
      </link>
      <joint name='crane_plus_shoulder_revolute_joint' type='revolute'>
        <child>crane_plus_shoulder_revolute_link</child>
        <parent>base_link</parent>
        <axis>
          <xyz>0 0 1</xyz>
          <limit>
            <lower>-2.617</lower>
            <upper>2.617</upper>
            <effort>30</effort>
            <velocity>1.571</velocity>
          </limit>
          <dynamics>
            <spring_reference>0</spring_reference>
            <spring_stiffness>0</spring_stiffness>
          </dynamics>
          <use_parent_model_frame>1</use_parent_model_frame>
        </axis>
      </joint>
      <link name='crane_plus_shoulder_flex_link'>
        <pose frame=''>-0.0163 0 0.0715 1.57079 -1.57079 -3.14159</pose>
        <inertial>
          <pose frame=''>0.0385 -0 0.00025 0 -0 0</pose>
          <mass>0.004</mass>
          <inertia>
            <ixx>4</ixx>
            <ixy>1.25117e-12</ixy>
            <ixz>2.99872e-09</ixz>
            <iyy>4</iyy>
            <iyz>9.62038e-15</iyz>
            <izz>4</izz>
          </inertia>
        </inertial>
        <collision name='crane_plus_shoulder_flex_link_collision'>
          <pose frame=''>0.0135 0 0 0 -0 0</pose>
          <geometry>
            <box>
              <size>0.05 0.032 0.038</size>
            </box>
          </geometry>
          <max_contacts>10</max_contacts>
          <surface>
            <contact>
              <ode/>
            </contact>
            <bounce/>
            <friction>
              <torsional>
                <ode/>
              </torsional>
              <ode/>
            </friction>
          </surface>
        </collision>
        <collision name='crane_plus_shoulder_flex_link_fixed_joint_lump__crane_plus_internal_upper_arm_upper_joiner_link_collision_1'>
          <pose frame=''>0.037 0 0 -1.57079 -0 1.57079</pose>
          <geometry>
            <box>
              <size>0.025 0.038 0.009</size>
            </box>
          </geometry>
          <max_contacts>10</max_contacts>
          <surface>
            <contact>
              <ode/>
            </contact>
            <bounce/>
            <friction>
              <torsional>
                <ode/>
              </torsional>
              <ode/>
            </friction>
          </surface>
        </collision>
        <collision name='crane_plus_shoulder_flex_link_fixed_joint_lump__crane_plus_internal_upper_arm_lower_joiner_link_collision_2'>
          <pose frame=''>0.046 -0 0 1.57079 -0 1.57079</pose>
          <geometry>
            <box>
              <size>0.025 0.038 0.009</size>
            </box>
          </geometry>
          <max_contacts>10</max_contacts>
          <surface>
            <contact>
              <ode/>
            </contact>
            <bounce/>
            <friction>
              <torsional>
                <ode/>
              </torsional>
              <ode/>
            </friction>
          </surface>
        </collision>
        <collision name='crane_plus_shoulder_flex_link_fixed_joint_lump__crane_plus_internal_lower_arm_servo_link_collision_3'>
          <pose frame=''>0.0695 -0 0 1e-06 -0 3.14159</pose>
          <geometry>
            <box>
              <size>0.05 0.032 0.038</size>
            </box>
          </geometry>
          <max_contacts>10</max_contacts>
          <surface>
            <contact>
              <ode/>
            </contact>
            <bounce/>
            <friction>
              <torsional>
                <ode/>
              </torsional>
              <ode/>
            </friction>
          </surface>
        </collision>
        <visual name='crane_plus_shoulder_flex_link_visual'>
          <pose frame=''>0.012 0 0 -1.57079 0 0</pose>
          <geometry>
            <mesh>
              <scale>0.001 0.001 0.001</scale>
              <uri>/home/charlene/catkin_ws/src/crane_plus_v2_motion_planning/crane_plus_description/meshes/ax12_box.stl</uri>
            </mesh>
          </geometry>
        </visual>
        <visual name='crane_plus_shoulder_flex_link_fixed_joint_lump__crane_plus_internal_upper_arm_upper_joiner_link_visual_1'>
          <pose frame=''>0.0415 0 0 3.14159 3e-06 -1.5708</pose>
          <geometry>
            <mesh>
              <scale>0.001 0.001 0.001</scale>
              <uri>/home/charlene/catkin_ws/src/crane_plus_v2_motion_planning/crane_plus_description/meshes/f3.stl</uri>
            </mesh>
          </geometry>
        </visual>
        <visual name='crane_plus_shoulder_flex_link_fixed_joint_lump__crane_plus_internal_upper_arm_lower_joiner_link_visual_2'>
          <pose frame=''>0.0415 0 0 0 -3e-06 -1.5708</pose>
          <geometry>
            <mesh>
              <scale>0.001 0.001 0.001</scale>
              <uri>/home/charlene/catkin_ws/src/crane_plus_v2_motion_planning/crane_plus_description/meshes/f3.stl</uri>
            </mesh>
          </geometry>
        </visual>
        <visual name='crane_plus_shoulder_flex_link_fixed_joint_lump__crane_plus_internal_lower_arm_servo_link_visual_3'>
          <pose frame=''>0.071 -0 0 -1.57079 -0 3.14159</pose>
          <geometry>
            <mesh>
              <scale>0.001 0.001 0.001</scale>
              <uri>/home/charlene/catkin_ws/src/crane_plus_v2_motion_planning/crane_plus_description/meshes/ax12_box.stl</uri>
            </mesh>
          </geometry>
        </visual>
        <self_collide>0</self_collide>
        <enable_wind>0</enable_wind>
        <kinematic>0</kinematic>
      </link>
      <joint name='crane_plus_shoulder_flex_joint' type='revolute'>
        <child>crane_plus_shoulder_flex_link</child>
        <parent>crane_plus_shoulder_revolute_link</parent>
        <axis>
          <xyz>1e-06 -1 -0</xyz>
          <limit>
            <lower>-1.7</lower>
            <upper>1.7</upper>
            <effort>30</effort>
            <velocity>1.571</velocity>
          </limit>
          <dynamics>
            <spring_reference>0</spring_reference>
            <spring_stiffness>0</spring_stiffness>
          </dynamics>
          <use_parent_model_frame>1</use_parent_model_frame>
        </axis>
      </joint>
      <link name='crane_plus_elbow_link'>
        <pose frame=''>-0.0163 0 0.1545 3.14159 1e-06 3.14159</pose>
        <inertial>
          <pose frame=''>0 0.000167 -0.044833 0 -0 0</pose>
          <mass>0.003</mass>
          <inertia>
            <ixx>3</ixx>
            <ixy>-2.56514e-14</ixy>
            <ixz>2.89562e-12</ixz>
            <iyy>3</iyy>
            <iyz>1.85833e-08</iyz>
            <izz>3</izz>
          </inertia>
        </inertial>
        <collision name='crane_plus_elbow_link_collision'>
          <pose frame=''>0 0 -0.0215 0 -0 0</pose>
          <geometry>
            <box>
              <size>0.028 0.0485 0.065</size>
            </box>
          </geometry>
          <max_contacts>10</max_contacts>
          <surface>
            <contact>
              <ode/>
            </contact>
            <bounce/>
            <friction>
              <torsional>
                <ode/>
              </torsional>
              <ode/>
            </friction>
          </surface>
        </collision>
        <collision name='crane_plus_elbow_link_fixed_joint_lump__crane_plus_internal_lower_arm_joiner_link_collision_1'>
          <pose frame=''>0 0 -0.057 3.14159 3e-06 3.14159</pose>
          <geometry>
            <box>
              <size>0.025 0.038 0.009</size>
            </box>
          </geometry>
          <max_contacts>10</max_contacts>
          <surface>
            <contact>
              <ode/>
            </contact>
            <bounce/>
            <friction>
              <torsional>
                <ode/>
              </torsional>
              <ode/>
            </friction>
          </surface>
        </collision>
        <collision name='crane_plus_elbow_link_fixed_joint_lump__crane_plus_internal_wrist_servo_link_collision_2'>
          <pose frame=''>0 0 -0.0805 -3.14159 -1.57079 1.5708</pose>
          <geometry>
            <box>
              <size>0.05 0.032 0.038</size>
            </box>
          </geometry>
          <max_contacts>10</max_contacts>
          <surface>
            <contact>
              <ode/>
            </contact>
            <bounce/>
            <friction>
              <torsional>
                <ode/>
              </torsional>
              <ode/>
            </friction>
          </surface>
        </collision>
        <visual name='crane_plus_elbow_link_visual'>
          <pose frame=''>0 0 0 1.57079 -0 0</pose>
          <geometry>
            <mesh>
              <scale>0.001 0.001 0.001</scale>
              <uri>/home/charlene/catkin_ws/src/crane_plus_v2_motion_planning/crane_plus_description/meshes/f4.stl</uri>
            </mesh>
          </geometry>
        </visual>
        <visual name='crane_plus_elbow_link_fixed_joint_lump__crane_plus_internal_lower_arm_joiner_link_visual_1'>
          <pose frame=''>0 0 -0.0525 -1.5708 -3e-06 3e-06</pose>
          <geometry>
            <mesh>
              <scale>0.001 0.001 0.001</scale>
              <uri>/home/charlene/catkin_ws/src/crane_plus_v2_motion_planning/crane_plus_description/meshes/f3.stl</uri>
            </mesh>
          </geometry>
        </visual>
        <visual name='crane_plus_elbow_link_fixed_joint_lump__crane_plus_internal_wrist_servo_link_visual_2'>
          <pose frame=''>0 0 -0.082 -3.14159 -1.57079 7e-06</pose>
          <geometry>
            <mesh>
              <scale>0.001 0.001 0.001</scale>
              <uri>/home/charlene/catkin_ws/src/crane_plus_v2_motion_planning/crane_plus_description/meshes/ax12_box.stl</uri>
            </mesh>
          </geometry>
        </visual>
        <self_collide>0</self_collide>
        <enable_wind>0</enable_wind>
        <kinematic>0</kinematic>
      </link>
      <joint name='crane_plus_elbow_joint' type='revolute'>
        <child>crane_plus_elbow_link</child>
        <parent>crane_plus_shoulder_flex_link</parent>
        <axis>
          <xyz>-0 1 1e-06</xyz>
          <limit>
            <lower>-2.3</lower>
            <upper>2.3</upper>
            <effort>30</effort>
            <velocity>1.571</velocity>
          </limit>
          <dynamics>
            <spring_reference>0</spring_reference>
            <spring_stiffness>0</spring_stiffness>
          </dynamics>
          <use_parent_model_frame>1</use_parent_model_frame>
        </axis>
      </joint>
      <link name='crane_plus_wrist_link'>
        <pose frame=''>-0.0163 -0 0.2485 -3.14159 -3e-06 -1e-06</pose>
        <inertial>
          <pose frame=''>0.0001 0.00992 -0.0326 0 -0 0</pose>
          <mass>0.005</mass>
          <inertia>
            <ixx>5</ixx>
            <ixy>6.35879e-09</ixy>
            <ixz>6.4509e-09</ixz>
            <iyy>5</iyy>
            <iyz>6.39837e-07</iyz>
            <izz>5</izz>
          </inertia>
        </inertial>
        <collision name='crane_plus_wrist_link_collision'>
          <pose frame=''>0 0 -0.00775 0 -0 0</pose>
          <geometry>
            <box>
              <size>0.025 0.0485 0.0375</size>
            </box>
          </geometry>
          <max_contacts>10</max_contacts>
          <surface>
            <contact>
              <ode/>
            </contact>
            <bounce/>
            <friction>
              <torsional>
                <ode/>
              </torsional>
              <ode/>
            </friction>
          </surface>
        </collision>
        <collision name='crane_plus_wrist_link_fixed_joint_lump__crane_plus_internal_wrist_joiner_link_collision_1'>
          <pose frame=''>0 0 -0.031 3.14159 3e-06 -1.5708</pose>
          <geometry>
            <box>
              <size>0.025 0.038 0.009</size>
            </box>
          </geometry>
          <max_contacts>10</max_contacts>
          <surface>
            <contact>
              <ode/>
            </contact>
            <bounce/>
            <friction>
              <torsional>
                <ode/>
              </torsional>
              <ode/>
            </friction>
          </surface>
        </collision>
        <collision name='crane_plus_wrist_link_fixed_joint_lump__crane_plus_internal_gripper_servo_link_collision_2'>
          <pose frame=''>-0 -0.0013 -0.0455 1.57079 -5e-06 1.57079</pose>
          <geometry>
            <box>
              <size>0.05 0.032 0.038</size>
            </box>
          </geometry>
          <max_contacts>10</max_contacts>
          <surface>
            <contact>
              <ode/>
            </contact>
            <bounce/>
            <friction>
              <torsional>
                <ode/>
              </torsional>
              <ode/>
            </friction>
          </surface>
        </collision>
        <collision name='crane_plus_wrist_link_fixed_joint_lump__crane_plus_internal_fixed_finger_joiner_link_collision_3'>
          <pose frame=''>0 0.0222 -0.0455 3.14159 -1.57079 -1.5708</pose>
          <geometry>
            <box>
              <size>0.025 0.038 0.009</size>
            </box>
          </geometry>
          <max_contacts>10</max_contacts>
          <surface>
            <contact>
              <ode/>
            </contact>
            <bounce/>
            <friction>
              <torsional>
                <ode/>
              </torsional>
              <ode/>
            </friction>
          </surface>
        </collision>
        <collision name='crane_plus_wrist_link_fixed_joint_lump__crane_plus_internal_fixed_finger_link_collision_4'>
          <pose frame=''>0 0.0267 -0.0455 -3.14159 1.57079 1.57079</pose>
          <geometry>
            <mesh>
              <scale>0.001 0.001 0.001</scale>
              <uri>/home/charlene/catkin_ws/src/crane_plus_v2_motion_planning/crane_plus_description/meshes/finger_fixed_collision.stl</uri>
            </mesh>
          </geometry>
          <max_contacts>10</max_contacts>
          <surface>
            <contact>
              <ode/>
            </contact>
            <bounce/>
            <friction>
              <torsional>
                <ode/>
              </torsional>
              <ode/>
            </friction>
          </surface>
        </collision>
        <visual name='crane_plus_wrist_link_visual'>
          <pose frame=''>0 0 0 1.57079 -0 0</pose>
          <geometry>
            <mesh>
              <scale>0.001 0.001 0.001</scale>
              <uri>/home/charlene/catkin_ws/src/crane_plus_v2_motion_planning/crane_plus_description/meshes/f2.stl</uri>
            </mesh>
          </geometry>
        </visual>
        <visual name='crane_plus_wrist_link_fixed_joint_lump__crane_plus_internal_wrist_joiner_link_visual_1'>
          <pose frame=''>0 0 -0.0265 -1.5708 -3e-06 1.5708</pose>
          <geometry>
            <mesh>
              <scale>0.001 0.001 0.001</scale>
              <uri>/home/charlene/catkin_ws/src/crane_plus_v2_motion_planning/crane_plus_description/meshes/f3.stl</uri>
            </mesh>
          </geometry>
        </visual>
        <visual name='crane_plus_wrist_link_fixed_joint_lump__crane_plus_internal_gripper_servo_link_visual_2'>
          <pose frame=''>-0 -0.0028 -0.0455 0 -5e-06 1.57079</pose>
          <geometry>
            <mesh>
              <scale>0.001 0.001 0.001</scale>
              <uri>/home/charlene/catkin_ws/src/crane_plus_v2_motion_planning/crane_plus_description/meshes/ax12_box.stl</uri>
            </mesh>
          </geometry>
        </visual>
        <visual name='crane_plus_wrist_link_fixed_joint_lump__crane_plus_internal_fixed_finger_joiner_link_visual_3'>
          <pose frame=''>0 0.0267 -0.0455 3.14159 1.57079 3e-06</pose>
          <geometry>
            <mesh>
              <scale>0.001 0.001 0.001</scale>
              <uri>/home/charlene/catkin_ws/src/crane_plus_v2_motion_planning/crane_plus_description/meshes/f3.stl</uri>
            </mesh>
          </geometry>
        </visual>
        <visual name='crane_plus_wrist_link_fixed_joint_lump__crane_plus_internal_fixed_finger_link_visual_4'>
          <pose frame=''>0 0.0267 -0.0455 -3.14159 1.57079 1.57079</pose>
          <geometry>
            <mesh>
              <scale>0.001 0.001 0.001</scale>
              <uri>/home/charlene/catkin_ws/src/crane_plus_v2_motion_planning/crane_plus_description/meshes/finger_fixed.stl</uri>
            </mesh>
          </geometry>
        </visual>
        <self_collide>0</self_collide>
        <enable_wind>0</enable_wind>
        <kinematic>0</kinematic>
      </link>
      <joint name='crane_plus_wrist_joint' type='revolute'>
        <child>crane_plus_wrist_link</child>
        <parent>crane_plus_elbow_link</parent>
        <axis>
          <xyz>1e-06 1 4e-06</xyz>
          <limit>
            <lower>-1.7</lower>
            <upper>1.7</upper>
            <effort>30</effort>
            <velocity>1.571</velocity>
          </limit>
          <dynamics>
            <spring_reference>0</spring_reference>
            <spring_stiffness>0</spring_stiffness>
          </dynamics>
          <use_parent_model_frame>1</use_parent_model_frame>
        </axis>
      </joint>
      <link name='crane_plus_moving_finger_link'>
        <pose frame=''>-0.0163 0.0148 0.294 -3.01724 -1.57079 -1.69515</pose>
        <inertial>
          <pose frame=''>0 -0 -0.01325 0 -0 0</pose>
          <mass>0.002</mass>
          <inertia>
            <ixx>2</ixx>
            <ixy>0</ixy>
            <ixz>0</ixz>
            <iyy>2</iyy>
            <iyz>-1.82434e-14</iyz>
            <izz>2</izz>
          </inertia>
        </inertial>
        <collision name='crane_plus_moving_finger_link_collision'>
          <pose frame=''>0 0 -0.00775 0 -0 0</pose>
          <geometry>
            <box>
              <size>0.025 0.0485 0.0375</size>
            </box>
          </geometry>
          <max_contacts>10</max_contacts>
          <surface>
            <contact>
              <ode/>
            </contact>
            <bounce/>
            <friction>
              <torsional>
                <ode/>
              </torsional>
              <ode/>
            </friction>
          </surface>
        </collision>
        <collision name='crane_plus_moving_finger_link_fixed_joint_lump__crane_plus_internal_moving_finger_plate_link_collision_1'>
          <pose frame=''>0 0 -0.0265 3.14159 -0 0</pose>
          <geometry>
            <mesh>
              <scale>0.001 0.001 0.001</scale>
              <uri>/home/charlene/catkin_ws/src/crane_plus_v2_motion_planning/crane_plus_description/meshes/finger_moving_collision.stl</uri>
            </mesh>
          </geometry>
          <max_contacts>10</max_contacts>
          <surface>
            <contact>
              <ode/>
            </contact>
            <bounce/>
            <friction>
              <torsional>
                <ode/>
              </torsional>
              <ode/>
            </friction>
          </surface>
        </collision>
        <visual name='crane_plus_moving_finger_link_visual'>
          <pose frame=''>0 0 0 1.57079 -0 0</pose>
          <geometry>
            <mesh>
              <scale>0.001 0.001 0.001</scale>
              <uri>/home/charlene/catkin_ws/src/crane_plus_v2_motion_planning/crane_plus_description/meshes/f2.stl</uri>
            </mesh>
          </geometry>
        </visual>
        <visual name='crane_plus_moving_finger_link_fixed_joint_lump__crane_plus_internal_moving_finger_plate_link_visual_1'>
          <pose frame=''>0 0 -0.0265 3.14159 -0 0</pose>
          <geometry>
            <mesh>
              <scale>0.001 0.001 0.001</scale>
              <uri>/home/charlene/catkin_ws/src/crane_plus_v2_motion_planning/crane_plus_description/meshes/finger_moving.stl</uri>
            </mesh>
          </geometry>
        </visual>
        <self_collide>0</self_collide>
        <enable_wind>0</enable_wind>
        <kinematic>0</kinematic>
      </link>
      <joint name='crane_plus_moving_finger_joint' type='revolute'>
        <child>crane_plus_moving_finger_link</child>
        <parent>crane_plus_wrist_link</parent>
        <axis>
          <xyz>1 1e-06 1e-06</xyz>
          <limit>
            <lower>-0.6</lower>
            <upper>0.65</upper>
            <effort>30</effort>
            <velocity>1.571</velocity>
          </limit>
          <dynamics>
            <spring_reference>0</spring_reference>
            <spring_stiffness>0</spring_stiffness>
          </dynamics>
          <use_parent_model_frame>1</use_parent_model_frame>
        </axis>
      </joint>
      <static>0</static>
      <plugin name='control' filename='libgazebo_ros_control.so'>
        <robotSimType>gazebo_ros_control/DefaultRobotHWSim</robotSimType>
        <robotNamespace>/</robotNamespace>
      </plugin>
      <plugin name='joint_state_publisher' filename='libgazebo_ros_joint_state_publisher.so'>
        <updateRate>100.0</updateRate>
        <jointName>crane_plus_shoulder_revolute_joint, crane_plus_shoulder_flex_joint, crane_plus_elbow_joint, crane_plus_wrist_joint, crane_plus_moving_finger_joint</jointName>
        <robotNamespace>/</robotNamespace>
      </plugin>
      <pose frame=''>0 0 0 0 -0 0</pose>
    </model>
    <state world_name='default'>
      <sim_time>5031 221000000</sim_time>
      <real_time>567 820361067</real_time>
      <wall_time>1548382589 623427891</wall_time>
      <iterations>1016161</iterations>
      <model name='crane_plus'>
        <pose frame=''>0 0 0 0 -0 0</pose>
        <scale>1 1 1</scale>
        <link name='base_link'>
          <pose frame=''>0 0 0 0 -0 0</pose>
          <velocity>2e-06 -1e-06 -4e-06 0 -0.00037 0.000367</velocity>
          <acceleration>0.000351 0.000317 0.00104 -1e-06 0.050722 -0.066002</acceleration>
          <wrench>1e-06 1e-06 3e-06 0 -0 0</wrench>
        </link>
        <link name='crane_plus_elbow_link'>
          <pose frame=''>-0.016307 0 0.1545 3.14159 3.4e-05 3.14159</pose>
          <velocity>-0.000656 -6e-06 -1e-05 0 0.009999 0.001017</velocity>
          <acceleration>0.353885 0.001117 0.001796 -0.000142 -1.15037 -2.00841</acceleration>
          <wrench>0.001062 3e-06 5e-06 0 -0 0</wrench>
        </link>
        <link name='crane_plus_moving_finger_link'>
          <pose frame=''>-0.01632 0.0148 0.294 -0.366836 -1.57023 1.93763</pose>
          <velocity>0.00017 -6e-06 -1e-05 0 -0.002226 0.001242</velocity>
          <acceleration>-0.378409 0.001148 0.001751 -3.14119 -1.16016 1.11843</acceleration>
          <wrench>-0.000757 2e-06 4e-06 0 -0 0</wrench>
        </link>
        <link name='crane_plus_shoulder_flex_link'>
          <pose frame=''>-0.0163 0 0.0715 1.57079 -1.5707 3.14159</pose>
          <velocity>-3.3e-05 -6e-06 -1e-05 0 -0.007501 0.00077</velocity>
          <acceleration>0.583214 0.001102 0.001847 -3.14155 0.707944 1.16244</acceleration>
          <wrench>0.002333 4e-06 7e-06 0 -0 0</wrench>
        </link>
        <link name='crane_plus_shoulder_revolute_link'>
          <pose frame=''>-0.0163 0 0.045 0 -0 0</pose>
          <velocity>-1.4e-05 -6e-06 -1e-05 0 -0.000735 0.00043</velocity>
          <acceleration>0.001979 0.0011 0.001818 -5e-06 0.124982 -1.90722</acceleration>
          <wrench>2e-06 1e-06 2e-06 0 -0 0</wrench>
        </link>
        <link name='crane_plus_wrist_link'>
          <pose frame=''>-0.016311 0 0.2485 -3.14159 -0.000206 -1e-06</pose>
          <velocity>0.000284 -6e-06 -1e-05 -0 -0.002122 0.001192</velocity>
          <acceleration>-0.510343 0.000942 0.001309 -3.14158 -1.13774 1.12066</acceleration>
          <wrench>-0.002552 5e-06 7e-06 0 -0 0</wrench>
        </link>
      </model>
      <model name='ground_plane'>
        <pose frame=''>0 0 0 0 -0 0</pose>
        <scale>1 1 1</scale>
        <link name='link'>
          <pose frame=''>0 0 0 0 -0 0</pose>
          <velocity>0 0 0 0 -0 0</velocity>
          <acceleration>0 0 0 0 -0 0</acceleration>
          <wrench>0 0 0 0 -0 0</wrench>
        </link>
      </model>
      <light name='sun'>
        <pose frame=''>0 0 10 0 -0 0</pose>
      </light>
      <light name='user_point_light_0'>
        <pose frame=''>0.012625 -0.010525 1 0 -0 0</pose>
      </light>
    </state>
  </world>
</sdf>
